Workbook
Name Formas: OFFSET('C-Das2'!$Y$6,0,0,SUM('C-Das2'!$AA$17-'C-Das2'!$AA$14),1)
Name Formas: OFFSET('[1]C-Das1'!$Y$6,0,0,SUM('[1]C-Das1'!$AA$18-'[1]C-Das1'!$AA$15),1)
Name Formas: OFFSET('C-Das1'!$Y$6,0,0,SUM('C-Das1'!$AA$18-'C-Das1'!$AA$15),1)
Name Segmento: OFFSET('[1]C-Das2'!$AB$6,0,0,SUM('[1]C-Das2'!$AD$7-'[1]C-Das2'!$AD$6),1)
Name Segmento: OFFSET('C-Das2'!$AB$6,0,0,SUM('C-Das2'!$AD$7-'C-Das2'!$AD$6),1)
Name SegmentoValor: OFFSET('[1]C-Das2'!$AC$6,0,0,COUNT('[1]C-Das2'!$AC$6:$AC$80),1)
Name SegmentoValor: OFFSET('C-Das2'!$AC$6,0,0,COUNT('C-Das2'!$AC$6:$AC$80),1)
Name ValorForma: OFFSET('C-Das2'!$Z$6,0,0,COUNT('C-Das2'!$Z$6:$Z$25),1)
Name ValorForma: OFFSET('[1]C-Das1'!$Z$6,0,0,COUNT('[1]C-Das1'!$Z$6:$Z$26),1)
Name ValorForma: OFFSET('C-Das1'!$Z$6,0,0,COUNT('C-Das1'!$Z$6:$Z$26),1)

Sheet Painel
K3: =SUM('C-Das1'!V5+'C-Das2'!V6) -> 57
L4: =TODAY() -> 46079
F5: =Q5 -> 0 | K5: =COUNTIF('Proc-G'!C7:C799,"Ativo") -> 134 | M5: Pode Esperar | N5: =COUNTIFS(Taref!$E$5:$E$6801,M5,Taref!$C$5:$C$6801,"<>Concluída") -> 0 | O5: PRAZO | P5: hoje | Q5: =COUNTIF('Proc-G'!U7:U8802,TODAY()) -> 0 | R5: =IF(Q5>0,IF(Q5=1,"Você tem 1 prazo em aberto para hoje!",CONCATENATE("Você tem ",Q5," prazos em aberto para hoje!")),"Você não tem prazos em aberto para hoje.") -> Você não tem prazos em aberto para hoje.
F6: =Q6 -> 0 | K6: =COUNTIF(Audie!G7:G800,"Agendada") -> 13 | M6: Pouco Urgente | N6: =COUNTIFS(Taref!$E$5:$E$6801,M6,Taref!$C$5:$C$6801,"<>Concluída") -> 0 | P6: 7 dias | Q6: =COUNTIFS('Proc-G'!AF7:AF9802,"<=7",'Proc-G'!AF7:AF9802,">0") -> 0 | R6: =IF(Q6>0,IF(Q6=1,"Você tem 1 prazo em aberto para os próximos 7 dias.",CONCATENATE("Você tem ",Q6," prazos em aberto para os próximos 7 dias!")),"Você não tem prazos em aberto para os próximos 7 dias.") -> Você não tem prazos em aberto para os próximos 7 dias.
M7: Requer Atenção | N7: =COUNTIFS(Taref!$E$5:$E$6801,M7,Taref!$C$5:$C$6801,"<>Concluída") -> 1
F8: =Q8 -> 0 | M8: Muito Urgente | N8: =COUNTIFS(Taref!$E$5:$E$6801,M8,Taref!$C$5:$C$6801,"<>Concluída") -> 0 | O8: audie | P8: hoje | Q8: =COUNTIF(Audie!C7:C8810,TODAY()) -> 0 | R8: =IF(Q8>0,IF(Q8=1,"Você tem 1 audiência agendada para hoje!",CONCATENATE("Você tem ",Q8," audiências agendadas para hoje!")),"Você não tem audiências agendadas para hoje.") -> Você não tem audiências agendadas para hoje.
F9: =Q9 -> 0 | M9: Exige Atenção Imediata | N9: =COUNTIFS(Taref!$E$5:$E$6801,M9,Taref!$C$5:$C$6801,"<>Concluída") -> 1 | P9: 7 dias | Q9: =COUNTIFS(Audie!D7:D8810,"<=7",Audie!D7:D8810,">0") -> 0 | R9: =IF(Q9>0,IF(Q9=1,"Você tem 1 audiência agendada para os próximos 7 dias!",CONCATENATE("Você tem ",Q9," audiências agendadas para os próximos dias!")),"Você não tem audiências agendadas para os próximos 7 dias.") -> Você não tem audiências agendadas para os próximos 7 dias.
D14: =IF('Clie-F'!I3>0,IF('Clie-F'!I3=1,"Você tem 1 cliente de aniversário hoje.",CONCATENATE("Você tem ",'Clie-F'!I3," clientes de aniversário hoje.")),"Você não tem clientes de aniversário hoje.") -> Você não tem clientes de aniversário hoje.
I15: =IF(H15<>"",COUNTIF('Proc-G'!M16:M408,Painel!H15),"")
I16: =IF(H16<>"",COUNTIF('Proc-G'!M17:M409,Painel!H16),"")
I17: =IF(H17<>"",COUNTIF('Proc-G'!M18:M410,Painel!H17),"")
I18: =IF(H18<>"",COUNTIF('Proc-G'!M19:M411,Painel!H18),"")
C19: =IF(Atend!J3>0,IF(Atend!J3=1,"Você tem que fazer contato com 1 cliente hoje.",CONCATENATE("Você tem que fazer contato com ",Atend!J3," clientes hoje.")),"Você não tem clientes para retornar o contato hoje.") -> Você não tem clientes para retornar o contato hoje. | I19: =IF(H19<>"",COUNTIF('Proc-G'!M20:M412,Painel!H19),"")
I20: =IF(H20<>"",COUNTIF('Proc-G'!M21:M413,Painel!H20),"")
I21: =IF(H21<>"",COUNTIF('Proc-G'!M22:M414,Painel!H21),"")
I22: =IF(H22<>"",COUNTIF('Proc-G'!M23:M415,Painel!H22),"")
I23: =IF(H23<>"",COUNTIF('Proc-G'!M24:M416,Painel!H23),"")
C33: =IF('Conf-G'!D23<>"",'Conf-G'!D23,"") | D33: =IF(C33<>"",COUNTIF('Proc-G'!M25:M417,Painel!C33),"")
C34: =IF('Conf-G'!D24<>"",'Conf-G'!D24,"") | D34: =IF(C34<>"",COUNTIF('Proc-G'!M26:M418,Painel!C34),"")
C35: =IF('Conf-G'!D25<>"",'Conf-G'!D25,"")
C36: =IF('Conf-G'!D26<>"",'Conf-G'!D26,"")
C37: =IF('Conf-G'!D27<>"",'Conf-G'!D27,"")

Sheet Gráfico1

Sheet Proc-G
I4: =CONCATENATE("PRAZOS PARA OS PRÓXIMOS 7 DIAS = ",COUNTIFS(AF7:AF9302,"<=7",AF7:AF9302,">0")) -> PRAZOS PARA OS PRÓXIMOS 7 DIAS = 0 | J4: =CONCATENATE("PRAZOS PARA HOJE = ", COUNTIF(U7:U9302,TODAY())) -> PRAZOS PARA HOJE = 0
B6: # | C6: Status | D6: Tipo | E6: Fase | F6: Nº do Processo | G6: Tipo de Ação | H6: Tipo de Cliente | I6: Cliente | J6: Qualificação | K6: Outro Envolvido | L6: Qualificação | M6: Advogado | N6: Valor da Causa | O6: Valor de Acordo / Sentença | P6: Valor Honorários em R$ | Q6: Valor Honorários em % | R6: Sucumbências | S6: Total em Honorários | T6: Prazo em Aberto? | U6: Data do Prazo | V6: Instância | W6: Comarca | X6: Vara | Y6: Observações | Z6: Data de Início do Processo | AA6: Data Fim do Processo | AB6: Duração | AC6: Resultado | AD6: Link do Processo | AE6: Link para Pasta de Documentos Digital | AF6: Diferença de dias (não apagar!)
B7: 1 | C7: Encerrado | D7: Judicial | E7: Fase de Sentença | F7: 1024471-68.2021.8.26.0506 | G7: Embargos à Execução | H7: Pessoa Jurídica | I7: Pepe Oficina | J7: Autor | K7: Bradesco Auto RE Companhia de Seguro | L7: Réu | M7: FERES JUNQUEIRA NAJM | N7: 62139.16 | O7: 62139.16 | S7: =IF(O7<>0,IF(P7<>0,SUM(P7+Q7*O7+O7*R7),IF(Q7<>0,SUM(P7+Q7*O7+O7*R7),"")),IF(P7<>0,SUM(P7+Q7*N7+N7*R7),IF(Q7<>0,SUM(P7+Q7*N7+N7*R7),""))) | T7: Não | V7: 1ª Instância | W7: Ribeirão Preto | X7: 2ª Vara Cível | Y7: Manifestar-se sobre o ato ordinatório sobre o processo de cancelamento do protesto perante ao Cartório | Z7: 44392 | AB7: =IFERROR(IF(Z7<>"",IF(AA7="",CONCATENATE(DATEDIF(Z7,TODAY(),"D")," dias"),CONCATENATE(DATEDIF(Z7,AA7,"D")," dias")),""),"") -> 1687 dias | AC7: Procedente | AD7: https://esaj.tjsp.jus.br/cpopg/show.do?processo.codigo=E2000LBKJ0000&processo.foro=506&processo.numero=1024471-68.2021.8.26.0506 | AF7: =DATEDIF(TODAY(),U7,"D") -> #NUM! | AG7: =IFERROR(IF(Z7<>"",IF(AA7="",DATEDIF(Z7,TODAY(),"D"),DATEDIF(Z7,AA7,"D")),""),"") -> 1687 | AI7: =IF(I7<>"",IF(F7<>"",CONCATENATE(I7," - ",G7," (",F7,")"),CONCATENATE(I7," - ",G7)),"") -> Pepe Oficina - Embargos à Execução (1024471-68.2021.8.26.0506) | AJ7: =IF(I7<>"",IF(F7<>"",CONCATENATE(I7," - ",G7," (",F7,")"),CONCATENATE(I7," - ",G7)),"") -> Pepe Oficina - Embargos à Execução (1024471-68.2021.8.26.0506)
B8: 2 | C8: Encerrado | D8: Judicial | E8: Fase de Sentença | F8: 1029547-15.2017.8.26.0506 | G8: Inventário | H8: Pessoa Física | I8: Maria Neide Ribas Silva | J8: Inventariante | K8: José Aparecido da Silva | L8: Inventariado | M8: FERES JUNQUEIRA NAJM | N8: 1000 | S8: =IF(O8<>0,IF(P8<>0,SUM(P8+Q8*O8+O8*R8),IF(Q8<>0,SUM(P8+Q8*O8+O8*R8),"")),IF(P8<>0,SUM(P8+Q8*N8+N8*R8),IF(Q8<>0,SUM(P8+Q8*N8+N8*R8),""))) | T8: Não | V8: 1ª Instância | W8: Ribeirão Preto | X8: 1ª Vara Familia e Sucessões | Y8: Saiu a Certidão de Objeto e Pé | Z8: 42907 | AA8: 44791 | AB8: =IFERROR(IF(Z8<>"",IF(AA8="",CONCATENATE(DATEDIF(Z8,TODAY(),"D")," dias"),CONCATENATE(DATEDIF(Z8,AA8,"D")," dias")),""),"") -> 1884 dias | AD8: https://esaj.tjsp.jus.br/cpopg/show.do?processo.codigo=E2000BLUQ0000&processo.foro=506&processo.numero=1029547-15.2017.8.26.0506 | AF8: =DATEDIF(TODAY(),U8,"D") -> #NUM! | AG8: =IFERROR(IF(Z8<>"",IF(AA8="",DATEDIF(Z8,TODAY(),"D"),DATEDIF(Z8,AA8,"D")),""),"") -> 1884 | AI8: =IF(I8<>"",IF(F8<>"",CONCATENATE(I8," - ",G8," (",F8,")"),CONCATENATE(I8," - ",G8)),"") -> Maria Neide Ribas Silva - Inventário (1029547-15.2017.8.26.0506) | AJ8: =IF(I8<>"",IF(F8<>"",CONCATENATE(I8," - ",G8," (",F8,")"),CONCATENATE(I8," - ",G8)),"") -> Maria Neide Ribas Silva - Inventário (1029547-15.2017.8.26.0506)
B9: 3 | C9: Encerrado | D9: Judicial | E9: Fase de Sentença | F9: 1001371-05.2019.8.26.0070 | G9: Ação Declaratória de Constitucionalidade | H9: Pessoa Física | I9: Arlene Sofiati Salgado | J9: Autor | K9: Banco ItauCard S/A | L9: Réu | M9: ADRIANO LOURENÇO MORAIS DOS SANTOS | N9: 5397.4 | O9: 5397.4 | S9: =IF(O9<>0,IF(P9<>0,SUM(P9+Q9*O9+O9*R9),IF(Q9<>0,SUM(P9+Q9*O9+O9*R9),"")),IF(P9<>0,SUM(P9+Q9*N9+N9*R9),IF(Q9<>0,SUM(P9+Q9*N9+N9*R9),""))) | T9: Não | V9: 1ª Instância | W9: Batatais | X9: 1ª Vara Cível | Y9: Aguardando a extinção do processo | Z9: 43593 | AB9: =IFERROR(IF(Z9<>"",IF(AA9="",CONCATENATE(DATEDIF(Z9,TODAY(),"D")," dias"),CONCATENATE(DATEDIF(Z9,AA9,"D")," dias")),""),"") -> 2486 dias | AC9: Procedente | AD9: https://esaj.tjsp.jus.br/cpopg/show.do?processo.codigo=1Y0001DVR0000&processo.foro=70&processo.numero=1001371-05.2019.8.26.0070 | AF9: =DATEDIF(TODAY(),U9,"D") -> #NUM! | AG9: =IFERROR(IF(Z9<>"",IF(AA9="",DATEDIF(Z9,TODAY(),"D"),DATEDIF(Z9,AA9,"D")),""),"") -> 2486 | AI9: =IF(I9<>"",IF(F9<>"",CONCATENATE(I9," - ",G9," (",F9,")"),CONCATENATE(I9," - ",G9)),"") -> Arlene Sofiati Salgado - Ação Declaratória de Constitucionalidade (1001371-05.2019.8.26.0070) | AJ9: =IF(I9<>"",IF(F9<>"",CONCATENATE(I9," - ",G9," (",F9,")"),CONCATENATE(I9," - ",G9)),"") -> Arlene Sofiati Salgado - Ação Declaratória de Constitucionalidade (1001371-05.2019.8.26.0070)
B10: 4 | C10: Ativo | D10: Judicial | E10: Fase de Sentença | F10: 1039671-28.2015.8.26.0506 | G10: Cumprimento de sentença | H10: Pessoa Física | I10: Maria Regina Dos Santos Geraldo | J10: Autor | K10: Banco do Brasil S/A | L10: Réu | M10: ADRIANO LOURENÇO MORAIS DOS SANTOS | N10: 75763.57 | S10: =IF(O10<>0,IF(P10<>0,SUM(P10+Q10*O10+O10*R10),IF(Q10<>0,SUM(P10+Q10*O10+O10*R10),"")),IF(P10<>0,SUM(P10+Q10*N10+N10*R10),IF(Q10<>0,SUM(P10+Q10*N10+N10*R10),""))) | T10: Não | V10: 1ª Instância | W10: São Paulo | X10: 1ª Vara Cível | Y10: Petição de produção de prova especificada - juntada - aguarando o despacho do Juiz | Z10: 42314 | AB10: =IFERROR(IF(Z10<>"",IF(AA10="",CONCATENATE(DATEDIF(Z10,TODAY(),"D")," dias"),CONCATENATE(DATEDIF(Z10,AA10,"D")," dias")),""),"") -> 3765 dias | AC10: Parcialmente Procedente | AD10: https://esaj.tjsp.jus.br/cpopg/show.do?processo.codigo=E20007N5Z0000&processo.foro=506&processo.numero=1039671-28.2015.8.26.0506 | AF10: =DATEDIF(TODAY(),U10,"D") -> #NUM! | AG10: =IFERROR(IF(Z10<>"",IF(AA10="",DATEDIF(Z10,TODAY(),"D"),DATEDIF(Z10,AA10,"D")),""),"") -> 3765 | AI10: =IF(I10<>"",IF(F10<>"",CONCATENATE(I10," - ",G10," (",F10,")"),CONCATENATE(I10," - ",G10)),"") -> Maria Regina Dos Santos Geraldo - Cumprimento de sentença (1039671-28.2015.8.26.0506) | AJ10: =IF(I10<>"",IF(F10<>"",CONCATENATE(I10," - ",G10," (",F10,")"),CONCATENATE(I10," - ",G10)),"") -> Maria Regina Dos Santos Geraldo - Cumprimento de sentença (1039671-28.2015.8.26.0506)
B11: 5 | C11: Encerrado | D11: Judicial | E11: Fase de Sentença | F11: 1015312-04.2021.8.26.0506 | G11: Rescisão de Contrato | H11: Pessoa Física | I11: Danielle Contin Nader | J11: Recorrido | K11: Cipreste Residencial Incorporadora Imobiliária Ltda. | L11: Recorrente | M11: FERES JUNQUEIRA NAJM | N11: 321500 | O11: 5089.12 | S11: =IF(O11<>0,IF(P11<>0,SUM(P11+Q11*O11+O11*R11),IF(Q11<>0,SUM(P11+Q11*O11+O11*R11),"")),IF(P11<>0,SUM(P11+Q11*N11+N11*R11),IF(Q11<>0,SUM(P11+Q11*N11+N11*R11),""))) | T11: Não | V11: 1ª Instância | W11: Ribeirão Preto | X11: 9ª Vara Cível | Y11: Arquivado Definitivamente - Extinto | Z11: 44319 | AA11: 45049 | AB11: =IFERROR(IF(Z11<>"",IF(AA11="",CONCATENATE(DATEDIF(Z11,TODAY(),"D")," dias"),CONCATENATE(DATEDIF(Z11,AA11,"D")," dias")),""),"") -> 730 dias | AC11: Parcialmente Procedente | AD11: https://esaj.tjsp.jus.br/cpopg/show.do?processo.codigo=E2000KWUO0000&processo.foro=506&processo.numero=1015312-04.2021.8.26.0506 | AF11: =DATEDIF(TODAY(),U11,"D") -> #NUM! | AG11: =IFERROR(IF(Z11<>"",IF(AA11="",DATEDIF(Z11,TODAY(),"D"),DATEDIF(Z11,AA11,"D")),""),"") -> 730 | AI11: =IF(I11<>"",IF(F11<>"",CONCATENATE(I11," - ",G11," (",F11,")"),CONCATENATE(I11," - ",G11)),"") -> Danielle Contin Nader - Rescisão de Contrato (1015312-04.2021.8.26.0506) | AJ11: =IF(I11<>"",IF(F11<>"",CONCATENATE(I11," - ",G11," (",F11,")"),CONCATENATE(I11," - ",G11)),"") -> Danielle Contin Nader - Rescisão de Contrato (1015312-04.2021.8.26.0506)
B12: 6 | C12: Encerrado | D12: Judicial | E12: Fase de Sentença | F12: 0004512-60.2023.8.26.0506 | G12: Cumprimento de sentença | H12: Pessoa Física | I12: Danielle Contin Nader | J12: Executante | K12: Cipreste Residencial Incorporadora Imobiliária Ltda. | L12: Executado | M12: FERES JUNQUEIRA NAJM | N12: 5089.12 | S12: =IF(O12<>0,IF(P12<>0,SUM(P12+Q12*O12+O12*R12),IF(Q12<>0,SUM(P12+Q12*O12+O12*R12),"")),IF(P12<>0,SUM(P12+Q12*N12+N12*R12),IF(Q12<>0,SUM(P12+Q12*N12+N12*R12),""))) | T12: Não | V12: 1ª Instância | W12: Ribeirão Preto | X12: 9ª Vara Cível | Y12: A outra parte juntou guia de pagamento de parte das custas | Z12: 44999 | AB12: =IFERROR(IF(Z12<>"",IF(AA12="",CONCATENATE(DATEDIF(Z12,TODAY(),"D")," dias"),CONCATENATE(DATEDIF(Z12,AA12,"D")," dias")),""),"") -> 1080 dias | AD12: https://esaj.tjsp.jus.br/cpopg/show.do?processo.codigo=E2000P7HZ0000&processo.foro=506&processo.numero=0004512-60.2023.8.26.0506 | AF12: =DATEDIF(TODAY(),U12,"D") -> #NUM! | AG12: =IFERROR(IF(Z12<>"",IF(AA12="",DATEDIF(Z12,TODAY(),"D"),DATEDIF(Z12,AA12,"D")),""),"") -> 1080 | AI12: =IF(I12<>"",IF(F12<>"",CONCATENATE(I12," - ",G12," (",F12,")"),CONCATENATE(I12," - ",G12)),"") -> Danielle Contin Nader - Cumprimento de sentença (0004512-60.2023.8.26.0506) | AJ12: =IF(I12<>"",IF(F12<>"",CONCATENATE(I12," - ",G12," (",F12,")"),CONCATENATE(I12," - ",G12)),"") -> Danielle Contin Nader - Cumprimento de sentença (0004512-60.2023.8.26.0506)
B13: 7 | C13: Encerrado | D13: Judicial | E13: Fase de Sentença | F13: 1015179-59.2021.8.26.0506 | G13: Fornecimento de Medicamento | H13: Pessoa Física | I13: Julio Cesar Borges | J13: Autor | K13: Ribeirão Preto/Estado/União | L13: Réu | M13: FERES JUNQUEIRA NAJM | N13: 368338.03 | S13: =IF(O13<>0,IF(P13<>0,SUM(P13+Q13*O13+O13*R13),IF(Q13<>0,SUM(P13+Q13*O13+O13*R13),"")),IF(P13<>0,SUM(P13+Q13*N13+N13*R13),IF(Q13<>0,SUM(P13+Q13*N13+N13*R13),""))) | T13: Não | V13: 1ª Instância | W13: Ribeirão Preto | X13: 1ª Vara da Fazenda | Y13: Encaminhado para a Justiça Federal | Z13: 44316 | AB13: =IFERROR(IF(Z13<>"",IF(AA13="",CONCATENATE(DATEDIF(Z13,TODAY(),"D")," dias"),CONCATENATE(DATEDIF(Z13,AA13,"D")," dias")),""),"") -> 1763 dias | AD13: https://esaj.tjsp.jus.br/cpopg/show.do?processo.codigo=E2000KWK90000&processo.foro=506&processo.numero=1015179-59.2021.8.26.0506 | AF13: =DATEDIF(TODAY(),U13,"D") -> #NUM! | AG13: =IFERROR(IF(Z13<>"",IF(AA13="",DATEDIF(Z13,TODAY(),"D"),DATEDIF(Z13,AA13,"D")),""),"") -> 1763 | AI13: =IF(I13<>"",IF(F13<>"",CONCATENATE(I13," - ",G13," (",F13,")"),CONCATENATE(I13," - ",G13)),"") -> Julio Cesar Borges - Fornecimento de Medicamento (1015179-59.2021.8.26.0506) | AJ13: =IF(I13<>"",IF(F13<>"",CONCATENATE(I13," - ",G13," (",F13,")"),CONCATENATE(I13," - ",G13)),"") -> Julio Cesar Borges - Fornecimento de Medicamento (1015179-59.2021.8.26.0506)
B14: 8 | C14: Encerrado | D14: Judicial | E14: Fase de Sentença | F14: 1025487-17.2021.8.26.0196 | G14: Ação Indenizatória | H14: Pessoa Jurídica | I14: Supermercados Big Compra Ltda. | J14: Requerido | K14: Angélica Cardoso de Oliveira Olaia | L14: Requerente | M14: FERES JUNQUEIRA NAJM | N14: 1000 | S14: =IF(O14<>0,IF(P14<>0,SUM(P14+Q14*O14+O14*R14),IF(Q14<>0,SUM(P14+Q14*O14+O14*R14),"")),IF(P14<>0,SUM(P14+Q14*N14+N14*R14),IF(Q14<>0,SUM(P14+Q14*N14+N14*R14),""))) | T14: Não | V14: 1ª Instância | W14: Franca | X14: 5ª Vara Cível | Y14: Aguardando Extinção do Processo | Z14: 44459 | AB14: =IFERROR(IF(Z14<>"",IF(AA14="",CONCATENATE(DATEDIF(Z14,TODAY(),"D")," dias"),CONCATENATE(DATEDIF(Z14,AA14,"D")," dias")),""),"") -> 1620 dias | AC14: Acordo | AD14: https://esaj.tjsp.jus.br/cpopg/show.do?processo.codigo=5G000C88A0000&processo.foro=196&processo.numero=1025487-17.2021.8.26.0196 | AF14: =DATEDIF(TODAY(),U14,"D") -> #NUM! | AG14: =IFERROR(IF(Z14<>"",IF(AA14="",DATEDIF(Z14,TODAY(),"D"),DATEDIF(Z14,AA14,"D")),""),"") -> 1620 | AI14: =IF(I14<>"",IF(F14<>"",CONCATENATE(I14," - ",G14," (",F14,")"),CONCATENATE(I14," - ",G14)),"") -> Supermercados Big Compra Ltda. - Ação Indenizatória (1025487-17.2021.8.26.0196) | AJ14: =IF(I14<>"",IF(F14<>"",CONCATENATE(I14," - ",G14," (",F14,")"),CONCATENATE(I14," - ",G14)),"") -> Supermercados Big Compra Ltda. - Ação Indenizatória (1025487-17.2021.8.26.0196)
B15: 9 | C15: Encerrado | D15: Judicial | E15: Fase Recursal | F15: 1026606-13.2021.8.26.0196 | G15: Ação Indenizatória | H15: Pessoa Jurídica | I15: Supermercados Big Compra Ltda. | J15: Requerido | K15: Joel Fonseca da Cunha | L15: Requerente | M15: FERES JUNQUEIRA NAJM | N15: 50000 | S15: =IF(O15<>0,IF(P15<>0,SUM(P15+Q15*O15+O15*R15),IF(Q15<>0,SUM(P15+Q15*O15+O15*R15),"")),IF(P15<>0,SUM(P15+Q15*N15+N15*R15),IF(Q15<>0,SUM(P15+Q15*N15+N15*R15),""))) | T15: Não | V15: Tribunal de Justiça - São Paulo | W15: Franca | X15: 1ª Vara Cível | Y15: Baixa definitiva | Z15: 44469 | AA15: 45359 | AB15: =IFERROR(IF(Z15<>"",IF(AA15="",CONCATENATE(DATEDIF(Z15,TODAY(),"D")," dias"),CONCATENATE(DATEDIF(Z15,AA15,"D")," dias")),""),"") -> 890 dias | AC15: Improcedente | AD15: https://esaj.tjsp.jus.br/cpopg/show.do?processo.codigo=5G000C9VM0000&processo.foro=196&processo.numero=1026606-13.2021.8.26.0196 | AF15: =DATEDIF(TODAY(),U15,"D") -> #NUM! | AG15: =IFERROR(IF(Z15<>"",IF(AA15="",DATEDIF(Z15,TODAY(),"D"),DATEDIF(Z15,AA15,"D")),""),"") -> 890 | AI15: =IF(I15<>"",IF(F15<>"",CONCATENATE(I15," - ",G15," (",F15,")"),CONCATENATE(I15," - ",G15)),"") -> Supermercados Big Compra Ltda. - Ação Indenizatória (1026606-13.2021.8.26.0196) | AJ15: =IF(I15<>"",IF(F15<>"",CONCATENATE(I15," - ",G15," (",F15,")"),CONCATENATE(I15," - ",G15)),"") -> Supermercados Big Compra Ltda. - Ação Indenizatória (1026606-13.2021.8.26.0196)
B16: 10 | C16: Encerrado | D16: Judicial | E16: Fase Recursal | F16: 1032968-71.2021.8.26.0506 | G16: Ação Indenizatória | H16: Pessoa Jurídica | I16: Supermercados Big Compra Ltda. | J16: Requerido | K16: Edielton de Sousa Vieira | L16: Requerente | M16: FERES JUNQUEIRA NAJM | N16: 20000 | S16: =IF(O16<>0,IF(P16<>0,SUM(P16+Q16*O16+O16*R16),IF(Q16<>0,SUM(P16+Q16*O16+O16*R16),"")),IF(P16<>0,SUM(P16+Q16*N16+N16*R16),IF(Q16<>0,SUM(P16+Q16*N16+N16*R16),""))) | T16: Não | V16: 1ª Instância | W16: Ribeirão Preto | X16: 2ª Vara Cível | Y16: Autos Redistribuídos para outra Seção do Tribunal de Justiça do Estado de São Paulo | Z16: 44456 | AB16: =IFERROR(IF(Z16<>"",IF(AA16="",CONCATENATE(DATEDIF(Z16,TODAY(),"D")," dias"),CONCATENATE(DATEDIF(Z16,AA16,"D")," dias")),""),"") -> 1623 dias | AD16: https://esaj.tjsp.jus.br/cpopg/show.do?processo.codigo=E2000LPHG0000&processo.foro=506&processo.numero=1032968-71.2021.8.26.0506 | AF16: =DATEDIF(TODAY(),U16,"D") -> #NUM! | AG16: =IFERROR(IF(Z16<>"",IF(AA16="",DATEDIF(Z16,TODAY(),"D"),DATEDIF(Z16,AA16,"D")),""),"") -> 1623 | AI16: =IF(I16<>"",IF(F16<>"",CONCATENATE(I16," - ",G16," (",F16,")"),CONCATENATE(I16," - ",G16)),"") -> Supermercados Big Compra Ltda. - Ação Indenizatória (1032968-71.2021.8.26.0506) | AJ16: =IF(I16<>"",IF(F16<>"",CONCATENATE(I16," - ",G16," (",F16,")"),CONCATENATE(I16," - ",G16)),"") -> Supermercados Big Compra Ltda. - Ação Indenizatória (1032968-71.2021.8.26.0506)
B17: 11 | C17: Ativo | D17: Judicial | E17: Fase Inicial | F17: 1041082-96.2021.8.26.0506 | G17: Declaração de Inexistência de Débito | H17: Pessoa Jurídica | I17: Brilho Auto Center | J17: Requerente | K17: Associação Imperial Paulista Proteção Automotiva | L17: Requerido | M17: FERES JUNQUEIRA NAJM | N17: 20332 | S17: =IF(O17<>0,IF(P17<>0,SUM(P17+Q17*O17+O17*R17),IF(Q17<>0,SUM(P17+Q17*O17+O17*R17),"")),IF(P17<>0,SUM(P17+Q17*N17+N17*R17),IF(Q17<>0,SUM(P17+Q17*N17+N17*R17),""))) | T17: Não | V17: 1ª Instância | W17: Ribeirão Preto | X17: 3ª Vara Cível | Y17: Foi juntada guia de pagamento de custas após tentativa de encontrar réu | Z17: 44497 | AB17: =IFERROR(IF(Z17<>"",IF(AA17="",CONCATENATE(DATEDIF(Z17,TODAY(),"D")," dias"),CONCATENATE(DATEDIF(Z17,AA17,"D")," dias")),""),"") -> 1582 dias | AD17: https://esaj.tjsp.jus.br/cpopg/show.do?processo.codigo=E2000M0HD0000&processo.foro=506&processo.numero=1041082-96.2021.8.26.0506 | AF17: =DATEDIF(TODAY(),U17,"D") -> #NUM! | AG17: =IFERROR(IF(Z17<>"",IF(AA17="",DATEDIF(Z17,TODAY(),"D"),DATEDIF(Z17,AA17,"D")),""),"") -> 1582 | AI17: =IF(I17<>"",IF(F17<>"",CONCATENATE(I17," - ",G17," (",F17,")"),CONCATENATE(I17," - ",G17)),"") -> Brilho Auto Center - Declaração de Inexistência de Débito (1041082-96.2021.8.26.0506) | AJ17: =IF(I17<>"",IF(F17<>"",CONCATENATE(I17," - ",G17," (",F17,")"),CONCATENATE(I17," - ",G17)),"") -> Brilho Auto Center - Declaração de Inexistência de Débito (1041082-96.2021.8.26.0506)
B18: 12 | C18: Encerrado | D18: Judicial | E18: Fase Inicial | F18: 1046715-88.2021.8.26.0506 | G18: Ação Indenizatória | H18: Pessoa Física | I18: Giuseppe Bonjovani de Paiva | J18: Requerente | K18: Azul Companhia de Seguros Gerais | L18: Requerido | M18: FERES JUNQUEIRA NAJM | N18: 43486 | S18: =IF(O18<>0,IF(P18<>0,SUM(P18+Q18*O18+O18*R18),IF(Q18<>0,SUM(P18+Q18*O18+O18*R18),"")),IF(P18<>0,SUM(P18+Q18*N18+N18*R18),IF(Q18<>0,SUM(P18+Q18*N18+N18*R18),""))) | T18: Não | V18: 1ª Instância | W18: Ribeirão Preto | X18: 3ª Vara Cível | Y18: Verificar constância de pagamentos do autor. Foi feito o pedido de homologação de acordo | Z18: 44533 | AB18: =IFERROR(IF(Z18<>"",IF(AA18="",CONCATENATE(DATEDIF(Z18,TODAY(),"D")," dias"),CONCATENATE(DATEDIF(Z18,AA18,"D")," dias")),""),"") -> 1546 dias | AD18: https://esaj.tjsp.jus.br/cpopg/show.do?processo.codigo=E2000M8N30000&processo.foro=506&processo.numero=1046715-88.2021.8.26.0506 | AF18: =DATEDIF(TODAY(),U18,"D") -> #NUM! | AG18: =IFERROR(IF(Z18<>"",IF(AA18="",DATEDIF(Z18,TODAY(),"D"),DATEDIF(Z18,AA18,"D")),""),"") -> 1546 | AI18: =IF(I18<>"",IF(F18<>"",CONCATENATE(I18," - ",G18," (",F18,")"),CONCATENATE(I18," - ",G18)),"") -> Giuseppe Bonjovani de Paiva - Ação Indenizatória (1046715-88.2021.8.26.0506) | AJ18: =IF(I18<>"",IF(F18<>"",CONCATENATE(I18," - ",G18," (",F18,")"),CONCATENATE(I18," - ",G18)),"") -> Giuseppe Bonjovani de Paiva - Ação Indenizatória (1046715-88.2021.8.26.0506)
B19: 13 | C19: Encerrado | D19: Judicial | E19: Fase de Execução | F19: 1032652-18.2021.8.26.0196 | G19: Ação de Título de Crédito | H19: Pessoa Jurídica | I19: Supermercados Big Compra Ltda. | J19: Requerente | K19: LS Interbank Fundo de Investimento | L19: Requerido | M19: FERES JUNQUEIRA NAJM | N19: 30354.54 | S19: =IF(O19<>0,IF(P19<>0,SUM(P19+Q19*O19+O19*R19),IF(Q19<>0,SUM(P19+Q19*O19+O19*R19),"")),IF(P19<>0,SUM(P19+Q19*N19+N19*R19),IF(Q19<>0,SUM(P19+Q19*N19+N19*R19),""))) | T19: Não | V19: 1ª Instância | W19: Franca | X19: 5ª Vara Cível | Y19: Extinto | Z19: 44544 | AA19: 45000 | AB19: =IFERROR(IF(Z19<>"",IF(AA19="",CONCATENATE(DATEDIF(Z19,TODAY(),"D")," dias"),CONCATENATE(DATEDIF(Z19,AA19,"D")," dias")),""),"") -> 456 dias | AC19: Extinto | AD19: https://esaj.tjsp.jus.br/cpopg/show.do?processo.codigo=5G000CL6A0000&processo.foro=196&processo.numero=1032652-18.2021.8.26.0196 | AF19: =DATEDIF(TODAY(),U19,"D") -> #NUM! | AG19: =IFERROR(IF(Z19<>"",IF(AA19="",DATEDIF(Z19,TODAY(),"D"),DATEDIF(Z19,AA19,"D")),""),"") -> 456 | AI19: =IF(I19<>"",IF(F19<>"",CONCATENATE(I19," - ",G19," (",F19,")"),CONCATENATE(I19," - ",G19)),"") -> Supermercados Big Compra Ltda. - Ação de Título de Crédito (1032652-18.2021.8.26.0196) | AJ19: =IF(I19<>"",IF(F19<>"",CONCATENATE(I19," - ",G19," (",F19,")"),CONCATENATE(I19," - ",G19)),"") -> Supermercados Big Compra Ltda. - Ação de Título de Crédito (1032652-18.2021.8.26.0196)
B20: 14 | C20: Encerrado | D20: Judicial | E20: Fase de Sentença | F20: 1003841-84.2021.8.26.0572 | G20: Ação de Título de Crédito | H20: Pessoa Jurídica | I20: Supermercados Big Compra Ltda. | J20: Requerente | K20: LS Interbank Fundo de Investimento | L20: Requerido | M20: FERES JUNQUEIRA NAJM | N20: 55192.01 | S20: =IF(O20<>0,IF(P20<>0,SUM(P20+Q20*O20+O20*R20),IF(Q20<>0,SUM(P20+Q20*O20+O20*R20),"")),IF(P20<>0,SUM(P20+Q20*N20+N20*R20),IF(Q20<>0,SUM(P20+Q20*N20+N20*R20),""))) | T20: Não | V20: 1ª Instância | W20: Sã Joaquim da Barra | X20: 1ª Vara Cível | Y20: Processo já transitou em julgado - pronto para realizar o cumprimento de sentença | Z20: 44540 | AA20: 45084 | AB20: =IFERROR(IF(Z20<>"",IF(AA20="",CONCATENATE(DATEDIF(Z20,TODAY(),"D")," dias"),CONCATENATE(DATEDIF(Z20,AA20,"D")," dias")),""),"") -> 544 dias | AC20: Extinto | AD20: https://esaj.tjsp.jus.br/cpopg/show.do?processo.codigo=FW0002JBM0000&processo.foro=572&processo.numero=1003841-84.2021.8.26.0572 | AF20: =DATEDIF(TODAY(),U20,"D") -> #NUM! | AG20: =IFERROR(IF(Z20<>"",IF(AA20="",DATEDIF(Z20,TODAY(),"D"),DATEDIF(Z20,AA20,"D")),""),"") -> 544 | AI20: =IF(I20<>"",IF(F20<>"",CONCATENATE(I20," - ",G20," (",F20,")"),CONCATENATE(I20," - ",G20)),"") -> Supermercados Big Compra Ltda. - Ação de Título de Crédito (1003841-84.2021.8.26.0572) | AJ20: =IF(I20<>"",IF(F20<>"",CONCATENATE(I20," - ",G20," (",F20,")"),CONCATENATE(I20," - ",G20)),"") -> Supermercados Big Compra Ltda. - Ação de Título de Crédito (1003841-84.2021.8.26.0572)
B21: 15 | C21: Encerrado | D21: Judicial | E21: Fase de Sentença | F21: 1000128-71.2022.8.26.0506 | G21: Ação Declaratória de Constitucionalidade | H21: Pessoa Jurídica | I21: Supermercados Big Compra Ltda. | J21: Requerido | K21: Silvana Quirino de Sousa | L21: Requerido | M21: FERES JUNQUEIRA NAJM | N21: 51432.62 | S21: =IF(O21<>0,IF(P21<>0,SUM(P21+Q21*O21+O21*R21),IF(Q21<>0,SUM(P21+Q21*O21+O21*R21),"")),IF(P21<>0,SUM(P21+Q21*N21+N21*R21),IF(Q21<>0,SUM(P21+Q21*N21+N21*R21),""))) | T21: Não | V21: 1ª Instância | W21: Ribeirão Preto | X21: 7ª Vara Cível | Y21: Aguardando o arquivamento e extinção | Z21: 44566 | AB21: =IFERROR(IF(Z21<>"",IF(AA21="",CONCATENATE(DATEDIF(Z21,TODAY(),"D")," dias"),CONCATENATE(DATEDIF(Z21,AA21,"D")," dias")),""),"") -> 1513 dias | AC21: Acordo | AD21: https://esaj.tjsp.jus.br/cpopg/show.do?processo.codigo=E2000MEVC0000&processo.foro=506&processo.numero=1000128-71.2022.8.26.0506 | AF21: =DATEDIF(TODAY(),U21,"D") -> #NUM! | AG21: =IFERROR(IF(Z21<>"",IF(AA21="",DATEDIF(Z21,TODAY(),"D"),DATEDIF(Z21,AA21,"D")),""),"") -> 1513 | AI21: =IF(I21<>"",IF(F21<>"",CONCATENATE(I21," - ",G21," (",F21,")"),CONCATENATE(I21," - ",G21)),"") -> Supermercados Big Compra Ltda. - Ação Declaratória de Constitucionalidade (1000128-71.2022.8.26.0506) | AJ21: =IF(I21<>"",IF(F21<>"",CONCATENATE(I21," - ",G21," (",F21,")"),CONCATENATE(I21," - ",G21)),"") -> Supermercados Big Compra Ltda. - Ação Declaratória de Constitucionalidade (1000128-71.2022.8.26.0506)
B22: 16 | C22: Encerrado | D22: Judicial | E22: Fase Recursal | F22: 1002154-72.2021.8.26.0572 | G22: Declaração de Inexistência de Débito | H22: Pessoa Jurídica | I22: Supermercados Big Compra Ltda. | J22: Requerido | K22: Patricia Alves dos Santos | L22: Requerente | M22: FERES JUNQUEIRA NAJM | N22: 15000 | S22: =IF(O22<>0,IF(P22<>0,SUM(P22+Q22*O22+O22*R22),IF(Q22<>0,SUM(P22+Q22*O22+O22*R22),"")),IF(P22<>0,SUM(P22+Q22*N22+N22*R22),IF(Q22<>0,SUM(P22+Q22*N22+N22*R22),""))) | T22: Não | V22: Tribunal de Justiça - São Paulo | W22: São Paulo | X22: 19ª Câmara Direito Privado | Y22: Aguardando o despacho do Juiz - OMNI é quem iria pagar | Z22: 44392 | AB22: =IFERROR(IF(Z22<>"",IF(AA22="",CONCATENATE(DATEDIF(Z22,TODAY(),"D")," dias"),CONCATENATE(DATEDIF(Z22,AA22,"D")," dias")),""),"") -> 1687 dias | AD22: https://esaj.tjsp.jus.br/cpopg/show.do?processo.codigo=FW0002GIO0000&processo.foro=572&processo.numero=1002154-72.2021.8.26.0572 | AF22: =DATEDIF(TODAY(),U22,"D") -> #NUM! | AG22: =IFERROR(IF(Z22<>"",IF(AA22="",DATEDIF(Z22,TODAY(),"D"),DATEDIF(Z22,AA22,"D")),""),"") -> 1687 | AI22: =IF(I22<>"",IF(F22<>"",CONCATENATE(I22," - ",G22," (",F22,")"),CONCATENATE(I22," - ",G22)),"") -> Supermercados Big Compra Ltda. - Declaração de Inexistência de Débito (1002154-72.2021.8.26.0572) | AJ22: =IF(I22<>"",IF(F22<>"",CONCATENATE(I22," - ",G22," (",F22,")"),CONCATENATE(I22," - ",G22)),"") -> Supermercados Big Compra Ltda. - Declaração de Inexistência de Débito (1002154-72.2021.8.26.0572)
B23: 17 | C23: Ativo | D23: Judicial | E23: Fase de Sentença | F23: 1016717-41.2022.8.26.0506 | G23: Declaração de Inexistência de Débito | H23: Pessoa Física | I23: Edson José Marques | J23: Requerente | K23: Banco Estado do Rio Grande do Sul S/A (Banrisul) | L23: Requerido | M23: FERES JUNQUEIRA NAJM | N23: 20063.69 | S23: =IF(O23<>0,IF(P23<>0,SUM(P23+Q23*O23+O23*R23),IF(Q23<>0,SUM(P23+Q23*O23+O23*R23),"")),IF(P23<>0,SUM(P23+Q23*N23+N23*R23),IF(Q23<>0,SUM(P23+Q23*N23+N23*R23),""))) | T23: Sim | V23: 1ª Instância | W23: Ribeirão Preto | X23: 8ª Vara Cível | Y23: Foi emitido despecho para serem feitas as alegações finais. | Z23: 44679 | AB23: =IFERROR(IF(Z23<>"",IF(AA23="",CONCATENATE(DATEDIF(Z23,TODAY(),"D")," dias"),CONCATENATE(DATEDIF(Z23,AA23,"D")," dias")),""),"") -> 1400 dias | AD23: https://esaj.tjsp.jus.br/cpopg/show.do?processo.codigo=E2000N56Z0000&processo.foro=506&processo.numero=1016717-41.2022.8.26.0506 | AF23: =DATEDIF(TODAY(),U23,"D") -> #NUM! | AG23: =IFERROR(IF(Z23<>"",IF(AA23="",DATEDIF(Z23,TODAY(),"D"),DATEDIF(Z23,AA23,"D")),""),"") -> 1400 | AI23: =IF(I23<>"",IF(F23<>"",CONCATENATE(I23," - ",G23," (",F23,")"),CONCATENATE(I23," - ",G23)),"") -> Edson José Marques - Declaração de Inexistência de Débito (1016717-41.2022.8.26.0506) | AJ23: =IF(I23<>"",IF(F23<>"",CONCATENATE(I23," - ",G23," (",F23,")"),CONCATENATE(I23," - ",G23)),"") -> Edson José Marques - Declaração de Inexistência de Débito (1016717-41.2022.8.26.0506)
B24: 18 | C24: Ativo | D24: Judicial | E24: Fase de Contestação | F24: 1017163-44.2022.8.26.0506 | G24: Declaração de Inexistência de Débito | H24: Pessoa Física | I24: Fernando José Pereira | J24: Requerente | K24: Banco C6 Consignado S/A | L24: Requerido | M24: FERES JUNQUEIRA NAJM | N24: 27993.22 | S24: =IF(O24<>0,IF(P24<>0,SUM(P24+Q24*O24+O24*R24),IF(Q24<>0,SUM(P24+Q24*O24+O24*R24),"")),IF(P24<>0,SUM(P24+Q24*N24+N24*R24),IF(Q24<>0,SUM(P24+Q24*N24+N24*R24),""))) | T24: Não | V24: 1ª Instância | W24: Ribeirão Preto | X24: 2ª Vara Cível | Y24: Foi feito o pedido para levantamento dos valores em depósito judicial | Z24: 44683 | AB24: =IFERROR(IF(Z24<>"",IF(AA24="",CONCATENATE(DATEDIF(Z24,TODAY(),"D")," dias"),CONCATENATE(DATEDIF(Z24,AA24,"D")," dias")),""),"") -> 1396 dias | AD24: https://esaj.tjsp.jus.br/cpopg/show.do?processo.codigo=E2000N5U80000&processo.foro=506&processo.numero=1017163-44.2022.8.26.0506 | AF24: =DATEDIF(TODAY(),U24,"D") -> #NUM! | AG24: =IFERROR(IF(Z24<>"",IF(AA24="",DATEDIF(Z24,TODAY(),"D"),DATEDIF(Z24,AA24,"D")),""),"") -> 1396 | AI24: =IF(I24<>"",IF(F24<>"",CONCATENATE(I24," - ",G24," (",F24,")"),CONCATENATE(I24," - ",G24)),"") -> Fernando José Pereira - Declaração de Inexistência de Débito (1017163-44.2022.8.26.0506) | AJ24: =IF(I24<>"",IF(F24<>"",CONCATENATE(I24," - ",G24," (",F24,")"),CONCATENATE(I24," - ",G24)),"") -> Fernando José Pereira - Declaração de Inexistência de Débito (1017163-44.2022.8.26.0506)
B25: 19 | C25: Encerrado | D25: Judicial | E25: Fase de Sentença | F25: 1001052-78.2022.8.26.0572 | G25: Ação Indenizatória | H25: Pessoa Jurídica | I25: Supermercados Big Compra Ltda. | J25: Requerido | K25: Manoel Jeronimo da Silva Neto | L25: Requerente | M25: FERES JUNQUEIRA NAJM | N25: 248000 | O25: 114000 | S25: =IF(O25<>0,IF(P25<>0,SUM(P25+Q25*O25+O25*R25),IF(Q25<>0,SUM(P25+Q25*O25+O25*R25),"")),IF(P25<>0,SUM(P25+Q25*N25+N25*R25),IF(Q25<>0,SUM(P25+Q25*N25+N25*R25),""))) | T25: Não | V25: 1ª Instância | W25: São Joaquim da Barra | X25: 2ª Vara Cível | Y25: Aguardando Homologar o Acordo | Z25: 44662 | AA25: 45091 | AB25: =IFERROR(IF(Z25<>"",IF(AA25="",CONCATENATE(DATEDIF(Z25,TODAY(),"D")," dias"),CONCATENATE(DATEDIF(Z25,AA25,"D")," dias")),""),"") -> 429 dias | AD25: https://esaj.tjsp.jus.br/cpopg/show.do?processo.codigo=FW0002LQ20000&processo.foro=572&processo.numero=1001052-78.2022.8.26.0572 | AF25: =DATEDIF(TODAY(),U25,"D") -> #NUM! | AG25: =IFERROR(IF(Z25<>"",IF(AA25="",DATEDIF(Z25,TODAY(),"D"),DATEDIF(Z25,AA25,"D")),""),"") -> 429 | AI25: =IF(I25<>"",IF(F25<>"",CONCATENATE(I25," - ",G25," (",F25,")"),CONCATENATE(I25," - ",G25)),"") -> Supermercados Big Compra Ltda. - Ação Indenizatória (1001052-78.2022.8.26.0572) | AJ25: =IF(I25<>"",IF(F25<>"",CONCATENATE(I25," - ",G25," (",F25,")"),CONCATENATE(I25," - ",G25)),"") -> Supermercados Big Compra Ltda. - Ação Indenizatória (1001052-78.2022.8.26.0572)
B26: 20 | C26: Encerrado | D26: Judicial | E26: Fase de Sentença | F26: 1021378-63.2022.8.26.0506 | G26: Seguro / Remoção / Vaga Técnica | H26: Pessoa Jurídica | I26: Leco Car | J26: Requerente | K26: HDI Seguros S/A | L26: Requerido | M26: FERES JUNQUEIRA NAJM | N26: 1000 | S26: =IF(O26<>0,IF(P26<>0,SUM(P26+Q26*O26+O26*R26),IF(Q26<>0,SUM(P26+Q26*O26+O26*R26),"")),IF(P26<>0,SUM(P26+Q26*N26+N26*R26),IF(Q26<>0,SUM(P26+Q26*N26+N26*R26),""))) | T26: Não | V26: 1ª Instância | W26: Ribeirão Preto | X26: 5ª Vara Cível | Y26: Extinto | Z26: 44705 | AA26: 45116 | AB26: =IFERROR(IF(Z26<>"",IF(AA26="",CONCATENATE(DATEDIF(Z26,TODAY(),"D")," dias"),CONCATENATE(DATEDIF(Z26,AA26,"D")," dias")),""),"") -> 411 dias | AD26: https://esaj.tjsp.jus.br/cpopg/show.do?processo.codigo=E2000NBJ30000&processo.foro=506&processo.numero=1021378-63.2022.8.26.0506 | AF26: =DATEDIF(TODAY(),U26,"D") -> #NUM! | AG26: =IFERROR(IF(Z26<>"",IF(AA26="",DATEDIF(Z26,TODAY(),"D"),DATEDIF(Z26,AA26,"D")),""),"") -> 411 | AI26: =IF(I26<>"",IF(F26<>"",CONCATENATE(I26," - ",G26," (",F26,")"),CONCATENATE(I26," - ",G26)),"") -> Leco Car - Seguro / Remoção / Vaga Técnica (1021378-63.2022.8.26.0506) | AJ26: =IF(I26<>"",IF(F26<>"",CONCATENATE(I26," - ",G26," (",F26,")"),CONCATENATE(I26," - ",G26)),"") -> Leco Car - Seguro / Remoção / Vaga Técnica (1021378-63.2022.8.26.0506)
B27: 21 | C27: Encerrado | D27: Judicial | E27: Fase de Sentença | F27: 1023475-36.2022.8.26.0506 | G27: Seguro / Remoção / Vaga Técnica | H27: Pessoa Jurídica | I27: Leco Car | J27: Requerente | K27: HDI Seguros S/A | L27: Requerido | M27: FERES JUNQUEIRA NAJM | N27: 11762 | S27: =IF(O27<>0,IF(P27<>0,SUM(P27+Q27*O27+O27*R27),IF(Q27<>0,SUM(P27+Q27*O27+O27*R27),"")),IF(P27<>0,SUM(P27+Q27*N27+N27*R27),IF(Q27<>0,SUM(P27+Q27*N27+N27*R27),""))) | T27: Não | V27: 1ª Instância | W27: Ribeirão Preto | X27: 5ª Vara Cível | Y27: Extinto | Z27: 44715 | AB27: =IFERROR(IF(Z27<>"",IF(AA27="",CONCATENATE(DATEDIF(Z27,TODAY(),"D")," dias"),CONCATENATE(DATEDIF(Z27,AA27,"D")," dias")),""),"") -> 1364 dias | AD27: https://esaj.tjsp.jus.br/cpopg/show.do?processo.codigo=E2000NEAN0000&processo.foro=506&processo.numero=1023475-36.2022.8.26.0506 | AF27: =DATEDIF(TODAY(),U27,"D") -> #NUM! | AG27: =IFERROR(IF(Z27<>"",IF(AA27="",DATEDIF(Z27,TODAY(),"D"),DATEDIF(Z27,AA27,"D")),""),"") -> 1364 | AI27: =IF(I27<>"",IF(F27<>"",CONCATENATE(I27," - ",G27," (",F27,")"),CONCATENATE(I27," - ",G27)),"") -> Leco Car - Seguro / Remoção / Vaga Técnica (1023475-36.2022.8.26.0506) | AJ27: =IF(I27<>"",IF(F27<>"",CONCATENATE(I27," - ",G27," (",F27,")"),CONCATENATE(I27," - ",G27)),"") -> Leco Car - Seguro / Remoção / Vaga Técnica (1023475-36.2022.8.26.0506)
B28: 22 | C28: Ativo | D28: Judicial | E28: Fase de Produção de Provas | F28: 1005036-74.2022.8.26.0506 | G28: Ação Indenizatória | H28: Pessoa Física | I28: Felipe Augusto Taveiros Palei | J28: Requerente | K28: Polimport - Comércio e Expostação (Americanas) | L28: Requerido | M28: FERES JUNQUEIRA NAJM | N28: 7173.59 | S28: =IF(O28<>0,IF(P28<>0,SUM(P28+Q28*O28+O28*R28),IF(Q28<>0,SUM(P28+Q28*O28+O28*R28),"")),IF(P28<>0,SUM(P28+Q28*N28+N28*R28),IF(Q28<>0,SUM(P28+Q28*N28+N28*R28),""))) | T28: Não | V28: 1ª Instância | W28: Ribeirão Preto | X28: 10ª Vara Cível | Y28: Foi feito um pedido de habilitação de novos patronos | Z28: 44606 | AB28: =IFERROR(IF(Z28<>"",IF(AA28="",CONCATENATE(DATEDIF(Z28,TODAY(),"D")," dias"),CONCATENATE(DATEDIF(Z28,AA28,"D")," dias")),""),"") -> 1473 dias | AD28: https://esaj.tjsp.jus.br/cpopg/show.do?processo.codigo=E2000MN7B0000&processo.foro=506&processo.numero=1005036-74.2022.8.26.0506 | AF28: =DATEDIF(TODAY(),U28,"D") -> #NUM! | AG28: =IFERROR(IF(Z28<>"",IF(AA28="",DATEDIF(Z28,TODAY(),"D"),DATEDIF(Z28,AA28,"D")),""),"") -> 1473 | AI28: =IF(I28<>"",IF(F28<>"",CONCATENATE(I28," - ",G28," (",F28,")"),CONCATENATE(I28," - ",G28)),"") -> Felipe Augusto Taveiros Palei - Ação Indenizatória (1005036-74.2022.8.26.0506) | AJ28: =IF(I28<>"",IF(F28<>"",CONCATENATE(I28," - ",G28," (",F28,")"),CONCATENATE(I28," - ",G28)),"") -> Felipe Augusto Taveiros Palei - Ação Indenizatória (1005036-74.2022.8.26.0506)
B29: 23 | C29: Ativo | D29: Judicial | E29: Fase Recursal | F29: 1000042-06.2022.8.26.0602 | G29: Declaração de Inexistência de Débito | H29: Pessoa Física | I29: Maria Angélica Cal Garcia Prado | J29: Requerente | K29: SPPREV - São Paulo Previdência | L29: Requerido | M29: FERES JUNQUEIRA NAJM | N29: 1000 | S29: =IF(O29<>0,IF(P29<>0,SUM(P29+Q29*O29+O29*R29),IF(Q29<>0,SUM(P29+Q29*O29+O29*R29),"")),IF(P29<>0,SUM(P29+Q29*N29+N29*R29),IF(Q29<>0,SUM(P29+Q29*N29+N29*R29),""))) | T29: Sim | V29: Tribunal de Justiça - São Paulo | W29: Sorocaba | X29: Juizado Especial Cível | Y29: Foi declarado vencido o Ministério da Fazenda. Aberto para cumprimento de sentença. | Z29: 44564 | AB29: =IFERROR(IF(Z29<>"",IF(AA29="",CONCATENATE(DATEDIF(Z29,TODAY(),"D")," dias"),CONCATENATE(DATEDIF(Z29,AA29,"D")," dias")),""),"") -> 1515 dias | AD29: https://esaj.tjsp.jus.br/cpopg/show.do?processo.codigo=GQ000QYKS0000&processo.foro=602&processo.numero=1000042-06.2022.8.26.0602 | AF29: =DATEDIF(TODAY(),U29,"D") -> #NUM! | AG29: =IFERROR(IF(Z29<>"",IF(AA29="",DATEDIF(Z29,TODAY(),"D"),DATEDIF(Z29,AA29,"D")),""),"") -> 1515 | AI29: =IF(I29<>"",IF(F29<>"",CONCATENATE(I29," - ",G29," (",F29,")"),CONCATENATE(I29," - ",G29)),"") -> Maria Angélica Cal Garcia Prado - Declaração de Inexistência de Débito (1000042-06.2022.8.26.0602) | AJ29: =IF(I29<>"",IF(F29<>"",CONCATENATE(I29," - ",G29," (",F29,")"),CONCATENATE(I29," - ",G29)),"") -> Maria Angélica Cal Garcia Prado - Declaração de Inexistência de Débito (1000042-06.2022.8.26.0602)
B30: 24 | C30: Encerrado | D30: Judicial | E30: Fase de Execução | F30: 1500252-07.2016.8.26.0506 | G30: Execução Fiscal | H30: Pessoa Jurídica | I30: Mister Ottani | J30: Requerido | K30: Prefeitura Municipal de Ribeirão Preto (Fazendo Municipal) | L30: Requerente | M30: FERES JUNQUEIRA NAJM | N30: 2622.4 | S30: =IF(O30<>0,IF(P30<>0,SUM(P30+Q30*O30+O30*R30),IF(Q30<>0,SUM(P30+Q30*O30+O30*R30),"")),IF(P30<>0,SUM(P30+Q30*N30+N30*R30),IF(Q30<>0,SUM(P30+Q30*N30+N30*R30),""))) | T30: Não | V30: 1ª Instância | W30: Ribeirão Preto | X30: Vara Execuções Fiscais | Y30: Aguardando a extinção do processo | Z30: 42978 | AB30: =IFERROR(IF(Z30<>"",IF(AA30="",CONCATENATE(DATEDIF(Z30,TODAY(),"D")," dias"),CONCATENATE(DATEDIF(Z30,AA30,"D")," dias")),""),"") -> 3101 dias | AD30: https://esaj.tjsp.jus.br/cpopg/show.do?processo.codigo=E20008C0H0000&processo.foro=506&processo.numero=1500252-07.2016.8.26.0506 | AF30: =DATEDIF(TODAY(),U30,"D") -> #NUM! | AG30: =IFERROR(IF(Z30<>"",IF(AA30="",DATEDIF(Z30,TODAY(),"D"),DATEDIF(Z30,AA30,"D")),""),"") -> 3101 | AI30: =IF(I30<>"",IF(F30<>"",CONCATENATE(I30," - ",G30," (",F30,")"),CONCATENATE(I30," - ",G30)),"") -> Mister Ottani - Execução Fiscal (1500252-07.2016.8.26.0506) | AJ30: =IF(I30<>"",IF(F30<>"",CONCATENATE(I30," - ",G30," (",F30,")"),CONCATENATE(I30," - ",G30)),"") -> Mister Ottani - Execução Fiscal (1500252-07.2016.8.26.0506)
B31: 25 | C31: Encerrado | D31: Judicial | E31: Fase de Execução | F31: 1505481-45.2016.8.26.0506 | G31: Execução Fiscal | H31: Pessoa Jurídica | I31: Mister Ottani | J31: Requerido | K31: Prefeitura Municipal de Ribeirão Preto (Fazendo Municipal) | L31: Requerente | M31: FERES JUNQUEIRA NAJM | N31: 2594.61 | S31: =IF(O31<>0,IF(P31<>0,SUM(P31+Q31*O31+O31*R31),IF(Q31<>0,SUM(P31+Q31*O31+O31*R31),"")),IF(P31<>0,SUM(P31+Q31*N31+N31*R31),IF(Q31<>0,SUM(P31+Q31*N31+N31*R31),""))) | T31: Não | V31: 1ª Instância | W31: Ribeirão Preto | X31: Vara Execuções Fiscais | Y31: Aguardando a extinção do processo | Z31: 42977 | AB31: =IFERROR(IF(Z31<>"",IF(AA31="",CONCATENATE(DATEDIF(Z31,TODAY(),"D")," dias"),CONCATENATE(DATEDIF(Z31,AA31,"D")," dias")),""),"") -> 3102 dias | AD31: https://esaj.tjsp.jus.br/cpopg/show.do?processo.codigo=E20009APM0000&processo.foro=506&processo.numero=1505481-45.2016.8.26.0506 | AF31: =DATEDIF(TODAY(),U31,"D") -> #NUM! | AG31: =IFERROR(IF(Z31<>"",IF(AA31="",DATEDIF(Z31,TODAY(),"D"),DATEDIF(Z31,AA31,"D")),""),"") -> 3102 | AI31: =IF(I31<>"",IF(F31<>"",CONCATENATE(I31," - ",G31," (",F31,")"),CONCATENATE(I31," - ",G31)),"") -> Mister Ottani - Execução Fiscal (1505481-45.2016.8.26.0506) | AJ31: =IF(I31<>"",IF(F31<>"",CONCATENATE(I31," - ",G31," (",F31,")"),CONCATENATE(I31," - ",G31)),"") -> Mister Ottani - Execução Fiscal (1505481-45.2016.8.26.0506)
B32: 26 | C32: Encerrado | D32: Judicial | E32: Fase de Sentença | F32: 1014033-06.2022.8.26.0196 | G32: Ação Indenizatória | H32: Pessoa Jurídica | I32: Supermercados Big Compra Ltda. | J32: Requerido | K32: Mirtes Helena Neves | L32: Requerente | M32: FERES JUNQUEIRA NAJM | N32: 12120 | S32: =IF(O32<>0,IF(P32<>0,SUM(P32+Q32*O32+O32*R32),IF(Q32<>0,SUM(P32+Q32*O32+O32*R32),"")),IF(P32<>0,SUM(P32+Q32*N32+N32*R32),IF(Q32<>0,SUM(P32+Q32*N32+N32*R32),""))) | T32: Não | V32: 1ª Instância | W32: Franca | X32: 2ª Vara Cível | Y32: Concluso para sentença | Z32: 44721 | AB32: =IFERROR(IF(Z32<>"",IF(AA32="",CONCATENATE(DATEDIF(Z32,TODAY(),"D")," dias"),CONCATENATE(DATEDIF(Z32,AA32,"D")," dias")),""),"") -> 1358 dias | AD32: https://esaj.tjsp.jus.br/cpopg/show.do?processo.codigo=5G000DHZG0000&processo.foro=196&processo.numero=1014033-06.2022.8.26.0196 | AF32: =DATEDIF(TODAY(),U32,"D") -> #NUM! | AG32: =IFERROR(IF(Z32<>"",IF(AA32="",DATEDIF(Z32,TODAY(),"D"),DATEDIF(Z32,AA32,"D")),""),"") -> 1358 | AI32: =IF(I32<>"",IF(F32<>"",CONCATENATE(I32," - ",G32," (",F32,")"),CONCATENATE(I32," - ",G32)),"") -> Supermercados Big Compra Ltda. - Ação Indenizatória (1014033-06.2022.8.26.0196) | AJ32: =IF(I32<>"",IF(F32<>"",CONCATENATE(I32," - ",G32," (",F32,")"),CONCATENATE(I32," - ",G32)),"") -> Supermercados Big Compra Ltda. - Ação Indenizatória (1014033-06.2022.8.26.0196)
B33: 27 | C33: Encerrado | D33: Judicial | E33: Fase Recursal | F33: 1034463-19.2022.8.26.0506 | G33: Seguro / Remoção / Vaga Técnica | H33: Pessoa Jurídica | I33: André Luís Massaro | J33: Requerente | K33: HDI Seguros S/A | L33: Requerido | M33: FERES JUNQUEIRA NAJM | N33: 1000 | S33: =IF(O33<>0,IF(P33<>0,SUM(P33+Q33*O33+O33*R33),IF(Q33<>0,SUM(P33+Q33*O33+O33*R33),"")),IF(P33<>0,SUM(P33+Q33*N33+N33*R33),IF(Q33<>0,SUM(P33+Q33*N33+N33*R33),""))) | T33: Não | V33: Tribunal de Justiça - São Paulo | W33: Rbeirão Preto | X33: 30ª Câmara de Direito Privado | Y33: Desembargador negou o provimento | Z33: 44778 | AA33: 45392 | AB33: =IFERROR(IF(Z33<>"",IF(AA33="",CONCATENATE(DATEDIF(Z33,TODAY(),"D")," dias"),CONCATENATE(DATEDIF(Z33,AA33,"D")," dias")),""),"") -> 614 dias | AD33: https://esaj.tjsp.jus.br/cpopg/show.do?processo.codigo=E2000NT950000&processo.foro=506&processo.numero=1034463-19.2022.8.26.0506 | AF33: =DATEDIF(TODAY(),U33,"D") -> #NUM! | AG33: =IFERROR(IF(Z33<>"",IF(AA33="",DATEDIF(Z33,TODAY(),"D"),DATEDIF(Z33,AA33,"D")),""),"") -> 614 | AI33: =IF(I33<>"",IF(F33<>"",CONCATENATE(I33," - ",G33," (",F33,")"),CONCATENATE(I33," - ",G33)),"") -> André Luís Massaro - Seguro / Remoção / Vaga Técnica (1034463-19.2022.8.26.0506) | AJ33: =IF(I33<>"",IF(F33<>"",CONCATENATE(I33," - ",G33," (",F33,")"),CONCATENATE(I33," - ",G33)),"") -> André Luís Massaro - Seguro / Remoção / Vaga Técnica (1034463-19.2022.8.26.0506)
B34: 28 | C34: Encerrado | D34: Judicial | E34: Fase de Sentença | F34: 1035727-71.2022.8.26.0506 | G34: Dissolução e Liquidação de Sociedade | H34: Pessoa Jurídica | I34: Brilho Auto Center | J34: Requerente | K34: Não tem | M34: FERES JUNQUEIRA NAJM | N34: 22500 | S34: =IF(O34<>0,IF(P34<>0,SUM(P34+Q34*O34+O34*R34),IF(Q34<>0,SUM(P34+Q34*O34+O34*R34),"")),IF(P34<>0,SUM(P34+Q34*N34+N34*R34),IF(Q34<>0,SUM(P34+Q34*N34+N34*R34),""))) | T34: Não | V34: 1ª Instância | W34: Ribeirão Preto | X34: 4ª Vara Cível | Y34: Extinto | Z34: 44785 | AA34: 45048 | AB34: =IFERROR(IF(Z34<>"",IF(AA34="",CONCATENATE(DATEDIF(Z34,TODAY(),"D")," dias"),CONCATENATE(DATEDIF(Z34,AA34,"D")," dias")),""),"") -> 263 dias | AD34: https://esaj.tjsp.jus.br/cpopg/show.do?processo.codigo=E2000NUZ60000&processo.foro=506&processo.numero=1035727-71.2022.8.26.0506 | AF34: =DATEDIF(TODAY(),U34,"D") -> #NUM! | AG34: =IFERROR(IF(Z34<>"",IF(AA34="",DATEDIF(Z34,TODAY(),"D"),DATEDIF(Z34,AA34,"D")),""),"") -> 263 | AI34: =IF(I34<>"",IF(F34<>"",CONCATENATE(I34," - ",G34," (",F34,")"),CONCATENATE(I34," - ",G34)),"") -> Brilho Auto Center - Dissolução e Liquidação de Sociedade (1035727-71.2022.8.26.0506) | AJ34: =IF(I34<>"",IF(F34<>"",CONCATENATE(I34," - ",G34," (",F34,")"),CONCATENATE(I34," - ",G34)),"") -> Brilho Auto Center - Dissolução e Liquidação de Sociedade (1035727-71.2022.8.26.0506)
B35: 29 | C35: Encerrado | D35: Judicial | E35: Fase de Sentença | F35: 0000171-21.2022.8.26.0572 | G35: Cumprimento de sentença | H35: Pessoa Jurídica | I35: Supermercados Big Compra Ltda. | J35: Requerido | K35: Patricia Alves dos Santos | L35: Requerente | M35: FERES JUNQUEIRA NAJM | N35: 15000 | S35: =IF(O35<>0,IF(P35<>0,SUM(P35+Q35*O35+O35*R35),IF(Q35<>0,SUM(P35+Q35*O35+O35*R35),"")),IF(P35<>0,SUM(P35+Q35*N35+N35*R35),IF(Q35<>0,SUM(P35+Q35*N35+N35*R35),""))) | T35: Não | V35: 1ª Instância | W35: São Joaquim da Barra | X35: 2ª Vara Cível | Y35: Concluso para Despacho | Z35: 44595 | AB35: =IFERROR(IF(Z35<>"",IF(AA35="",CONCATENATE(DATEDIF(Z35,TODAY(),"D")," dias"),CONCATENATE(DATEDIF(Z35,AA35,"D")," dias")),""),"") -> 1484 dias | AD35: https://esaj.tjsp.jus.br/cpopg/show.do?processo.codigo=FW0002KAK0000&processo.foro=572&processo.numero=0000171-21.2022.8.26.0572 | AF35: =DATEDIF(TODAY(),U35,"D") -> #NUM! | AG35: =IFERROR(IF(Z35<>"",IF(AA35="",DATEDIF(Z35,TODAY(),"D"),DATEDIF(Z35,AA35,"D")),""),"") -> 1484 | AI35: =IF(I35<>"",IF(F35<>"",CONCATENATE(I35," - ",G35," (",F35,")"),CONCATENATE(I35," - ",G35)),"") -> Supermercados Big Compra Ltda. - Cumprimento de sentença (0000171-21.2022.8.26.0572) | AJ35: =IF(I35<>"",IF(F35<>"",CONCATENATE(I35," - ",G35," (",F35,")"),CONCATENATE(I35," - ",G35)),"") -> Supermercados Big Compra Ltda. - Cumprimento de sentença (0000171-21.2022.8.26.0572)
B36: 30 | C36: Encerrado | D36: Judicial | E36: Fase de Sentença | F36: 1014765-61.2021.8.26.0506 | G36: Ação Civil Pública | H36: Pessoa Jurídica | I36: Supermercados Big Compra Ltda. | J36: Requerido | K36: Ministério Público do Estado de São Paulo | L36: Requerente | M36: FERES JUNQUEIRA NAJM | N36: 2000000 | S36: =IF(O36<>0,IF(P36<>0,SUM(P36+Q36*O36+O36*R36),IF(Q36<>0,SUM(P36+Q36*O36+O36*R36),"")),IF(P36<>0,SUM(P36+Q36*N36+N36*R36),IF(Q36<>0,SUM(P36+Q36*N36+N36*R36),""))) | T36: Não | V36: 1ª Instância | W36: Ribeirão Preto | X36: 2ª Vara Cível | Y36: Extinto | Z36: 44314 | AA36: 45008 | AB36: =IFERROR(IF(Z36<>"",IF(AA36="",CONCATENATE(DATEDIF(Z36,TODAY(),"D")," dias"),CONCATENATE(DATEDIF(Z36,AA36,"D")," dias")),""),"") -> 694 dias | AC36: Acordo | AD36: https://esaj.tjsp.jus.br/cpopg/show.do?processo.codigo=E2000KVYD0000&processo.foro=506&processo.numero=1014765-61.2021.8.26.0506 | AF36: =DATEDIF(TODAY(),U36,"D") -> #NUM! | AG36: =IFERROR(IF(Z36<>"",IF(AA36="",DATEDIF(Z36,TODAY(),"D"),DATEDIF(Z36,AA36,"D")),""),"") -> 694 | AI36: =IF(I36<>"",IF(F36<>"",CONCATENATE(I36," - ",G36," (",F36,")"),CONCATENATE(I36," - ",G36)),"") -> Supermercados Big Compra Ltda. - Ação Civil Pública (1014765-61.2021.8.26.0506) | AJ36: =IF(I36<>"",IF(F36<>"",CONCATENATE(I36," - ",G36," (",F36,")"),CONCATENATE(I36," - ",G36)),"") -> Supermercados Big Compra Ltda. - Ação Civil Pública (1014765-61.2021.8.26.0506)
B37: 31 | C37: Encerrado | D37: Judicial | E37: Fase de Produção de Provas | F37: 1044093-02.2022.8.26.0506 | G37: Seguro / Remoção / Vaga Técnica | H37: Pessoa Jurídica | I37: Pepe Oficina | J37: Requerente | K37: HDI Seguros S/A | L37: Requerido | M37: FERES JUNQUEIRA NAJM | N37: 4800 | S37: =IF(O37<>0,IF(P37<>0,SUM(P37+Q37*O37+O37*R37),IF(Q37<>0,SUM(P37+Q37*O37+O37*R37),"")),IF(P37<>0,SUM(P37+Q37*N37+N37*R37),IF(Q37<>0,SUM(P37+Q37*N37+N37*R37),""))) | T37: Não | V37: 1ª Instância | W37: Ribeirão Preto | X37: 8ª Vara Cível | Y37: Aguardando a decisão do Juiz - 1ª Instância | Z37: 44896 | AA37: 45414 | AB37: =IFERROR(IF(Z37<>"",IF(AA37="",CONCATENATE(DATEDIF(Z37,TODAY(),"D")," dias"),CONCATENATE(DATEDIF(Z37,AA37,"D")," dias")),""),"") -> 518 dias | AD37: https://esaj.tjsp.jus.br/cpopg/show.do?processo.codigo=E2000O7KO0000&processo.foro=506&processo.numero=1044093-02.2022.8.26.0506 | AF37: =DATEDIF(TODAY(),U37,"D") -> #NUM! | AG37: =IFERROR(IF(Z37<>"",IF(AA37="",DATEDIF(Z37,TODAY(),"D"),DATEDIF(Z37,AA37,"D")),""),"") -> 518 | AI37: =IF(I37<>"",IF(F37<>"",CONCATENATE(I37," - ",G37," (",F37,")"),CONCATENATE(I37," - ",G37)),"") -> Pepe Oficina - Seguro / Remoção / Vaga Técnica (1044093-02.2022.8.26.0506) | AJ37: =IF(I37<>"",IF(F37<>"",CONCATENATE(I37," - ",G37," (",F37,")"),CONCATENATE(I37," - ",G37)),"") -> Pepe Oficina - Seguro / Remoção / Vaga Técnica (1044093-02.2022.8.26.0506)
B38: 32 | C38: Ativo | D38: Judicial | E38: Fase de Produção de Provas | F38: 1003735-88.2022.8.26.0572 | G38: Ação Indenizatória | H38: Pessoa Jurídica | I38: Supermercados Big Compra Ltda. | J38: Requerido | K38: Tiago Martins Alexandre da Silva | L38: Requerente | M38: FERES JUNQUEIRA NAJM | N38: 6021.98 | S38: =IF(O38<>0,IF(P38<>0,SUM(P38+Q38*O38+O38*R38),IF(Q38<>0,SUM(P38+Q38*O38+O38*R38),"")),IF(P38<>0,SUM(P38+Q38*N38+N38*R38),IF(Q38<>0,SUM(P38+Q38*N38+N38*R38),""))) | T38: Não | V38: 1ª Instância | W38: São Joaquim da Barra | X38: 2ª Vara Cível | Y38: Aguardando a realização da Perícia - Petição de juntada feita. Perita não se manifestou | Z38: 44882 | AB38: =IFERROR(IF(Z38<>"",IF(AA38="",CONCATENATE(DATEDIF(Z38,TODAY(),"D")," dias"),CONCATENATE(DATEDIF(Z38,AA38,"D")," dias")),""),"") -> 1197 dias | AD38: https://esaj.tjsp.jus.br/cpopg/show.do?processo.codigo=FW0002PYK0000&processo.foro=572&processo.numero=1003735-88.2022.8.26.0572 | AF38: =DATEDIF(TODAY(),U38,"D") -> #NUM! | AG38: =IFERROR(IF(Z38<>"",IF(AA38="",DATEDIF(Z38,TODAY(),"D"),DATEDIF(Z38,AA38,"D")),""),"") -> 1197 | AI38: =IF(I38<>"",IF(F38<>"",CONCATENATE(I38," - ",G38," (",F38,")"),CONCATENATE(I38," - ",G38)),"") -> Supermercados Big Compra Ltda. - Ação Indenizatória (1003735-88.2022.8.26.0572) | AJ38: =IF(I38<>"",IF(F38<>"",CONCATENATE(I38," - ",G38," (",F38,")"),CONCATENATE(I38," - ",G38)),"") -> Supermercados Big Compra Ltda. - Ação Indenizatória (1003735-88.2022.8.26.0572)
B39: 33 | C39: Encerrado | D39: Judicial | E39: Fase de Contestação | F39: 1052312-04.2022.8.26.0506 | G39: Ação Monitória | H39: Pessoa Jurídica | I39: Pepe Oficina | J39: Requerente | K39: Antônio Carlos Principessa Junior | L39: Embargante | M39: FERES JUNQUEIRA NAJM | N39: 6944.7 | S39: =IF(O39<>0,IF(P39<>0,SUM(P39+Q39*O39+O39*R39),IF(Q39<>0,SUM(P39+Q39*O39+O39*R39),"")),IF(P39<>0,SUM(P39+Q39*N39+N39*R39),IF(Q39<>0,SUM(P39+Q39*N39+N39*R39),""))) | T39: Não | V39: Tribunal de Justiça - São Paulo | W39: Ribeirão Preto | X39: 3ª Vara Cível | Y39: Feito o Agravo em Resp | Z39: 44888 | AB39: =IFERROR(IF(Z39<>"",IF(AA39="",CONCATENATE(DATEDIF(Z39,TODAY(),"D")," dias"),CONCATENATE(DATEDIF(Z39,AA39,"D")," dias")),""),"") -> 1191 dias | AD39: https://esaj.tjsp.jus.br/cpopg/show.do?processo.codigo=E2000OJDL0000&processo.foro=506&processo.numero=1052312-04.2022.8.26.0506 | AF39: =DATEDIF(TODAY(),U39,"D") -> #NUM! | AG39: =IFERROR(IF(Z39<>"",IF(AA39="",DATEDIF(Z39,TODAY(),"D"),DATEDIF(Z39,AA39,"D")),""),"") -> 1191 | AI39: =IF(I39<>"",IF(F39<>"",CONCATENATE(I39," - ",G39," (",F39,")"),CONCATENATE(I39," - ",G39)),"") -> Pepe Oficina - Ação Monitória (1052312-04.2022.8.26.0506) | AJ39: =IF(I39<>"",IF(F39<>"",CONCATENATE(I39," - ",G39," (",F39,")"),CONCATENATE(I39," - ",G39)),"") -> Pepe Oficina - Ação Monitória (1052312-04.2022.8.26.0506)
B40: 34 | C40: Encerrado | D40: Judicial | E40: Fase Inicial | F40: 1003462-79.2023.8.26.0506 | G40: Ação de Cumprimento de Garantia | H40: Pessoa Jurídica | I40: Pepe Oficina | J40: Autor | K40: Chigado Pneumatic Brasil Ltda. | L40: Réu | M40: FERES JUNQUEIRA NAJM | N40: 949.79 | S40: =IF(O40<>0,IF(P40<>0,SUM(P40+Q40*O40+O40*R40),IF(Q40<>0,SUM(P40+Q40*O40+O40*R40),"")),IF(P40<>0,SUM(P40+Q40*N40+N40*R40),IF(Q40<>0,SUM(P40+Q40*N40+N40*R40),""))) | T40: Não | V40: 1ª Instância | W40: Ribeirão Preto | X40: Juizado Especial Cível | Y40: Aguardando a extinção do processo | Z40: 44957 | AB40: =IFERROR(IF(Z40<>"",IF(AA40="",CONCATENATE(DATEDIF(Z40,TODAY(),"D")," dias"),CONCATENATE(DATEDIF(Z40,AA40,"D")," dias")),""),"") -> 1122 dias | AD40: https://esaj.tjsp.jus.br/cpopg/show.do?processo.codigo=E2000OXQM0000&processo.foro=506&processo.numero=1003462-79.2023.8.26.0506 | AF40: =DATEDIF(TODAY(),U40,"D") -> #NUM! | AG40: =IFERROR(IF(Z40<>"",IF(AA40="",DATEDIF(Z40,TODAY(),"D"),DATEDIF(Z40,AA40,"D")),""),"") -> 1122 | AI40: =IF(I40<>"",IF(F40<>"",CONCATENATE(I40," - ",G40," (",F40,")"),CONCATENATE(I40," - ",G40)),"") -> Pepe Oficina - Ação de Cumprimento de Garantia (1003462-79.2023.8.26.0506) | AJ40: =IF(I40<>"",IF(F40<>"",CONCATENATE(I40," - ",G40," (",F40,")"),CONCATENATE(I40," - ",G40)),"") -> Pepe Oficina - Ação de Cumprimento de Garantia (1003462-79.2023.8.26.0506)
B41: 35 | C41: Encerrado | D41: Judicial | E41: Fase Inicial | F41: 0004874-47.2018.8.13.0329 | G41: Dissolução e Liquidação de Sociedade | H41: Pessoa Jurídica | I41: New Truck Comércio de Peças e Funilaria Ltda. | J41: Autor | K41: Associação Imperial Paulista Proteção Automotiva | L41: Requerido | M41: FERES JUNQUEIRA NAJM | S41: =IF(O41<>0,IF(P41<>0,SUM(P41+Q41*O41+O41*R41),IF(Q41<>0,SUM(P41+Q41*O41+O41*R41),"")),IF(P41<>0,SUM(P41+Q41*N41+N41*R41),IF(Q41<>0,SUM(P41+Q41*N41+N41*R41),""))) | T41: Não | V41: 1ª Instância | W41: Minas Gerais | Y41: Arquivado Definitivamente - Extinto | AA41: 45072 | AB41: =IFERROR(IF(Z41<>"",IF(AA41="",CONCATENATE(DATEDIF(Z41,TODAY(),"D")," dias"),CONCATENATE(DATEDIF(Z41,AA41,"D")," dias")),""),"") | AD41: https://pje-consulta-publica.tjmg.jus.br/pje/ConsultaPublica/DetalheProcessoConsultaPublica/listView.seam?ca=2ab5cd883fa2879c658851801c83892e5673fabd47590f8a | AF41: =DATEDIF(TODAY(),U41,"D") -> #NUM! | AG41: =IFERROR(IF(Z41<>"",IF(AA41="",DATEDIF(Z41,TODAY(),"D"),DATEDIF(Z41,AA41,"D")),""),"") | AI41: =IF(I41<>"",IF(F41<>"",CONCATENATE(I41," - ",G41," (",F41,")"),CONCATENATE(I41," - ",G41)),"") -> New Truck Comércio de Peças e Funilaria Ltda. - Dissolução e Liquidação de Sociedade (0004874-47.2018.8.13.0329) | AJ41: =IF(I41<>"",IF(F41<>"",CONCATENATE(I41," - ",G41," (",F41,")"),CONCATENATE(I41," - ",G41)),"") -> New Truck Comércio de Peças e Funilaria Ltda. - Dissolução e Liquidação de Sociedade (0004874-47.2018.8.13.0329)
B42: 36 | C42: Ativo | D42: Judicial | E42: Fase Inicial | F42: 5269532-14.2022..8.13.0024 | G42: Reconvenção | H42: Pessoa Jurídica | I42: New Truck Comércio de Peças e Funilaria Ltda. | J42: Requerido | K42: Beneficios Blue | L42: Requerente | M42: FERES JUNQUEIRA NAJM | S42: =IF(O42<>0,IF(P42<>0,SUM(P42+Q42*O42+O42*R42),IF(Q42<>0,SUM(P42+Q42*O42+O42*R42),"")),IF(P42<>0,SUM(P42+Q42*N42+N42*R42),IF(Q42<>0,SUM(P42+Q42*N42+N42*R42),""))) | T42: Não | W42: Minas Gerais | Y42: Concluso para sentença | AB42: =IFERROR(IF(Z42<>"",IF(AA42="",CONCATENATE(DATEDIF(Z42,TODAY(),"D")," dias"),CONCATENATE(DATEDIF(Z42,AA42,"D")," dias")),""),"") | AF42: =DATEDIF(TODAY(),U42,"D") -> #NUM! | AG42: =IFERROR(IF(Z42<>"",IF(AA42="",DATEDIF(Z42,TODAY(),"D"),DATEDIF(Z42,AA42,"D")),""),"") | AI42: =IF(I42<>"",IF(F42<>"",CONCATENATE(I42," - ",G42," (",F42,")"),CONCATENATE(I42," - ",G42)),"") -> New Truck Comércio de Peças e Funilaria Ltda. - Reconvenção (5269532-14.2022..8.13.0024) | AJ42: =IF(I42<>"",IF(F42<>"",CONCATENATE(I42," - ",G42," (",F42,")"),CONCATENATE(I42," - ",G42)),"") -> New Truck Comércio de Peças e Funilaria Ltda. - Reconvenção (5269532-14.2022..8.13.0024)
B43: 37 | C43: Ativo | D43: Judicial | E43: Fase de Execução | F43: 1066730-69.2020.8.26.0100 | G43: Dissolução e Liquidação de Sociedade | H43: Pessoa Jurídica | I43: New Truck Comércio de Peças e Funilaria Ltda. | J43: Requerente | K43: Ctr. Itaborai - Centro de tratamento de residuos Itaborai | L43: Requerido | M43: FERES JUNQUEIRA NAJM | N43: 8.2391981e+08 | S43: =IF(O43<>0,IF(P43<>0,SUM(P43+Q43*O43+O43*R43),IF(Q43<>0,SUM(P43+Q43*O43+O43*R43),"")),IF(P43<>0,SUM(P43+Q43*N43+N43*R43),IF(Q43<>0,SUM(P43+Q43*N43+N43*R43),""))) | T43: Não | V43: 1ª Instância | W43: São Paulo | X43: Vara de Falências e Recuperação | Y43: Aguardando o despacho do Juiz | Z43: 44041 | AB43: =IFERROR(IF(Z43<>"",IF(AA43="",CONCATENATE(DATEDIF(Z43,TODAY(),"D")," dias"),CONCATENATE(DATEDIF(Z43,AA43,"D")," dias")),""),"") -> 2038 dias | AD43: https://esaj.tjsp.jus.br/cpopg/show.do?processo.codigo=2S001ABF50000&processo.foro=100&processo.numero=1066730-69.2020.8.26.0100 | AF43: =DATEDIF(TODAY(),U43,"D") -> #NUM! | AG43: =IFERROR(IF(Z43<>"",IF(AA43="",DATEDIF(Z43,TODAY(),"D"),DATEDIF(Z43,AA43,"D")),""),"") -> 2038 | AI43: =IF(I43<>"",IF(F43<>"",CONCATENATE(I43," - ",G43," (",F43,")"),CONCATENATE(I43," - ",G43)),"") -> New Truck Comércio de Peças e Funilaria Ltda. - Dissolução e Liquidação de Sociedade (1066730-69.2020.8.26.0100) | AJ43: =IF(I43<>"",IF(F43<>"",CONCATENATE(I43," - ",G43," (",F43,")"),CONCATENATE(I43," - ",G43)),"") -> New Truck Comércio de Peças e Funilaria Ltda. - Dissolução e Liquidação de Sociedade (1066730-69.2020.8.26.0100)
B44: 38 | C44: Ativo | D44: Judicial | E44: Fase Inicial | F44: 1004265-62.2023.8.26.0506 | G44: Ação de Cumprimento de Garantia | H44: Pessoa Jurídica | I44: Regina Célia Guarita Crochiquia e Outros | J44: Requerente | K44: Hyundai Caoa do Brasil Ltda | L44: Requerido | M44: FERES JUNQUEIRA NAJM | N44: 33151.27 | S44: =IF(O44<>0,IF(P44<>0,SUM(P44+Q44*O44+O44*R44),IF(Q44<>0,SUM(P44+Q44*O44+O44*R44),"")),IF(P44<>0,SUM(P44+Q44*N44+N44*R44),IF(Q44<>0,SUM(P44+Q44*N44+N44*R44),""))) | T44: Não | V44: 1ª Instância | W44: Ribeirão Preto | X44: 7ª Vara Cível | Y44: Aguardando pronunciamento do CEJUSC | Z44: 44963 | AB44: =IFERROR(IF(Z44<>"",IF(AA44="",CONCATENATE(DATEDIF(Z44,TODAY(),"D")," dias"),CONCATENATE(DATEDIF(Z44,AA44,"D")," dias")),""),"") -> 1116 dias | AD44: https://esaj.tjsp.jus.br/cpopg/show.do?processo.codigo=E2000OYWO0000&processo.foro=506&processo.numero=1004265-62.2023.8.26.0506 | AF44: =DATEDIF(TODAY(),U44,"D") -> #NUM! | AG44: =IFERROR(IF(Z44<>"",IF(AA44="",DATEDIF(Z44,TODAY(),"D"),DATEDIF(Z44,AA44,"D")),""),"") -> 1116 | AI44: =IF(I44<>"",IF(F44<>"",CONCATENATE(I44," - ",G44," (",F44,")"),CONCATENATE(I44," - ",G44)),"") -> Regina Célia Guarita Crochiquia e Outros - Ação de Cumprimento de Garantia (1004265-62.2023.8.26.0506) | AJ44: =IF(I44<>"",IF(F44<>"",CONCATENATE(I44," - ",G44," (",F44,")"),CONCATENATE(I44," - ",G44)),"") -> Regina Célia Guarita Crochiquia e Outros - Ação de Cumprimento de Garantia (1004265-62.2023.8.26.0506)
...

Sheet Proc-D
B4: SELECIONE O PROCESSO →
B5: STATUS | C5: =IF(D5<>0,D5,"-") -> #N/A | D5: =INDEX('Proc-G'!C7:C88401,MATCH($C$4,'Proc-G'!AI7:AI88401,0)) -> #N/A
B6: PRAZO EM ABERTO? | C6: =IF(D6<>0,IF(D6="Não","Não",CONCATENATE("Sim (",TEXT(E6,"dd/mm/aaaa"),")")),"-") -> #N/A | D6: =INDEX('Proc-G'!T7:T88401,MATCH($C$4,'Proc-G'!AI7:AI88401,0)) -> #N/A | E6: =INDEX('Proc-G'!U7:U88401,MATCH($C$4,'Proc-G'!AI7:AI88401,0)) -> #N/A
B7: TIPO | C7: =IF(D7<>0,D7,"-") -> #N/A | D7: =INDEX('Proc-G'!D7:D88401,MATCH($C$4,'Proc-G'!AI7:AI88401,0)) -> #N/A
B8: FASE | C8: =IF(D8<>0,D8,"-") -> #N/A | D8: =INDEX('Proc-G'!E7:E88401,MATCH($C$4,'Proc-G'!AI7:AI88401,0)) -> #N/A
B9: QUALIFICAÇÃO DO CLIENTE | C9: =IF(D9<>0,D9,"-") -> #N/A | D9: =INDEX('Proc-G'!J7:J88401,MATCH($C$4,'Proc-G'!AI7:AI88401,0)) -> #N/A
